Workbook

Sheet Decisions
A1: Expected values — Benchmark Portfolio (portfolio_id 3)
A2: Roadmap 0.2. Computed BY HAND, before the capabilities exist, so there is an independent reference to check them against.
A3: Do NOT update these numbers to match code output. If the code disagrees, one of the two is wrong and that must be resolved deliberately.
A5: HOW TO USE THIS WORKBOOK
A6: Yellow cells | B6: You fill these in. Everything else is a formula and recalculates.
A7: Blue text | B7: Hardcoded input taken from the seed data.
A8: Black text | B8: Formula.
A9: Order of work | B9: 1) Decisions below 2) Positions 3) Allocation sheets 4) Volatility 5) Answers
A11: Provenance
A12: Computed on | B12: 03.09.2026 18:38 (Berlin)
A13: Price source | B13: Yahoo Finance via Yfinance
A14: Price as-of date | B14: 46268
A16: Part 0 — Decisions
A17: These are the point of the exercise. Each is a choice the code has to encode somewhere, and it is better made here than accidentally inside an agent.
A19: # | B19: Decision | C19: Choice | D19: Why
A20: D1 | B20: Allocation by market value or cost basis? | C20: market value | D20: Allocation means current exposure. Cost-basis allocation tells you what you paid, which is irrelevant to risk. Every professional report uses market value, and IPS limits are written against it. Cost basis matters only for P&L and tax lots.
A21: D2 | B21: Does cash count in the allocation denominator? | C21: include cash | D21: Cash is an asset class and holding it is a positioning decision. If you're 20% cash, saying "equities are 79% of invested" hides that. Benchmark 2.1 checks concentration against your IPS, and IPS limits are expressed against total portfolio value. Denominator = total including cash.
A22: D3 | B22: Are unsectored holdings reported explicitly, or excluded from the sector denominator? | C22: Report explicitly, denominator = total invested. | D22: This is the one where the wrong choice is actively misleading. "Technology is 58%" is true only against the $137,500 sectored subset; against the portfolio it's 28%. With 51.7% unsectored, silently dropping it inflates every sector figure roughly twofold. Report (no sector) 51.67% as its own line so the percentages sum to 100%. Your own principles point the same way, and Part 3b's "what it did not do" has a natural place for it.
A23: D4 | B23: Is P&L total return or price return? | C23: price return | D23: This one is forced by the data model, not chosen: Dividend has no portfolio_id, so no dividend can be attributed to a portfolio. Total return isn't computable today. The honest move is to compute price return and say so in the output. It also becomes a schema to-do — JNJ, JPM, NEE, VNQ and TLT all pay, so the understatement is material.
A24: D5 | B24: Volatility on daily or weekly returns? | C24: daily | D24: ~250 observations over twelve months versus ~52 weekly. Weekly reduces microstructure noise but 52 points is a thin estimate.
A25: D6 | B25: Annualisation factor? | C25: 252 | D25: Must match D5. (Weekly would be 52.)
A26: D7 | B26: Which of the five volatility implementations is canonical? | C26: quant/risk_metrics.py is canonical for return-series volatility. A new portfolio_volatility(weights, cov_matrix) goes there too, since none of the five computes portfolio-level vol. analytics_tools.py and optimization/base.py delegate to it. backtest/metrics.py and the inline engine.py:523 are scoped backtest-internal, not general-purpose.
A29: Note on D5/D6/D7
A30: Benchmark 1.3 passes when the basis of calculation is traceable, so the expected answer must carry D5, D6 and the window — not just the number.

Sheet Positions
A1: Part 1 — Positions
A2: Fill in column G (current price). Everything else computes. Cost basis follows mechanically from the seed data.
A4: Ticker | B4: Asset class | C4: Sector | D4: Qty | E4: Avg price ($) | F4: Cost basis ($) | G4: Current price ($) | H4: Market value ($) | I4: P&L abs ($) | J4: P&L % | K4: Purchase date | L4: Wt. of invested | M4: Wt. of total
A5: SPY | B5: Equity | C5: (none) | D5: 100 | E5: 500 | F5: =D5*E5 -> 50000 | G5: 765.16 | H5: =IF(G5="","",D5*G5) -> 76516 | I5: =IF(H5="","",H5-F5) -> 26516 | J5: =IF(H5="","",I5/F5) -> 0.53032 | K5: 2024-01-15 | L5: =IF($H$15="","",H5/$H$15) -> 0.19385838 | M5: =IF($H$16="","",H5/$H$16) -> 0.18653317
A6: AAPL | B6: Equity | C6: Technology | D6: 200 | E6: 200 | F6: =D6*E6 -> 40000 | G6: 324.96 | H6: =IF(G6="","",D6*G6) -> 64992 | I6: =IF(H6="","",H6-F6) -> 24992 | J6: =IF(H6="","",I6/F6) -> 0.6248 | K6: 2024-02-20 | L6: =IF($H$15="","",H6/$H$15) -> 0.16466156 | M6: =IF($H$16="","",H6/$H$16) -> 0.15843959
A7: MSFT | B7: Equity | C7: Technology | D7: 100 | E7: 400 | F7: =D7*E7 -> 40000 | G7: 496.82 | H7: =IF(G7="","",D7*G7) -> 49682 | I7: =IF(H7="","",H7-F7) -> 9682 | J7: =IF(H7="","",I7/F7) -> 0.24205 | K7: 2024-03-18 | L7: =IF($H$15="","",H7/$H$15) -> 0.12587266 | M7: =IF($H$16="","",H7/$H$16) -> 0.12111638
A8: JNJ | B8: Equity | C8: Healthcare | D8: 150 | E8: 150 | F8: =D8*E8 -> 22500 | G8: 275.21 | H8: =IF(G8="","",D8*G8) -> 41281.5 | I8: =IF(H8="","",H8-F8) -> 18781.5 | J8: =IF(H8="","",I8/F8) -> 0.83473333 | K8: 2024-05-06 | L8: =IF($H$15="","",H8/$H$15) -> 0.10458943 | M8: =IF($H$16="","",H8/$H$16) -> 0.10063737
A9: JPM | B9: Equity | C9: Financials | D9: 100 | E9: 200 | F9: =D9*E9 -> 20000 | G9: 356.22 | H9: =IF(G9="","",D9*G9) -> 35622 | I9: =IF(H9="","",H9-F9) -> 15622 | J9: =IF(H9="","",I9/F9) -> 0.7811 | K9: 2024-07-15 | L9: =IF($H$15="","",H9/$H$15) -> 0.090250709 | M9: =IF($H$16="","",H9/$H$16) -> 0.08684046
A10: NEE | B10: Equity | C10: Utilities | D10: 200 | E10: 75 | F10: =D10*E10 -> 15000 | G10: 83.1 | H10: =IF(G10="","",D10*G10) -> 16620 | I10: =IF(H10="","",H10-F10) -> 1620 | J10: =IF(H10="","",I10/F10) -> 0.108 | K10: 2024-09-09 | L10: =IF($H$15="","",H10/$H$15) -> 0.042107877 | M10: =IF($H$16="","",H10/$H$16) -> 0.040516772
A11: TLT | B11: Fixed Income | C11: (none) | D11: 500 | E11: 90 | F11: =D11*E11 -> 45000 | G11: 81.95 | H11: =IF(G11="","",D11*G11) -> 40975 | I11: =IF(H11="","",H11-F11) -> -4025 | J11: =IF(H11="","",I11/F11) -> -0.089444444 | K11: 2025-01-13 | L11: =IF($H$15="","",H11/$H$15) -> 0.10381289 | M11: =IF($H$16="","",H11/$H$16) -> 0.099890176
A12: GLD | B12: Commodity | C12: (none) | D12: 100 | E12: 250 | F12: =D12*E12 -> 25000 | G12: 402.78 | H12: =IF(G12="","",D12*G12) -> 40278 | I12: =IF(H12="","",H12-F12) -> 15278 | J12: =IF(H12="","",I12/F12) -> 0.61112 | K12: 2025-03-10 | L12: =IF($H$15="","",H12/$H$15) -> 0.102047 | M12: =IF($H$16="","",H12/$H$16) -> 0.098191007
A13: VNQ | B13: Real Estate | C13: (none) | D13: 300 | E13: 90 | F13: =D13*E13 -> 27000 | G13: 95.78 | H13: =IF(G13="","",D13*G13) -> 28734 | I13: =IF(H13="","",H13-F13) -> 1734 | J13: =IF(H13="","",I13/F13) -> 0.064222222 | K13: 2025-06-02 | L13: =IF($H$15="","",H13/$H$15) -> 0.072799502 | M13: =IF($H$16="","",H13/$H$16) -> 0.070048671
A14: CASH | B14: Cash | C14: (none) | F14: 15500 | H14: 15500 | M14: =IF($H$16="","",H14/$H$16) -> 0.0377864
A15: Total invested | F15: =SUM(F5:F13) -> 284500 | H15: =IF(COUNT(H5:H13)<9,"",SUM(H5:H13)) -> 394700.5 | I15: =IF(H15="","",H15-F15) -> 110200.5 | J15: =IF(H15="","",I15/F15) -> 0.38734798 | L15: =IF(H15="","",SUM(L5:L13)) -> 1
A16: Total incl. cash | F16: =F15+F14 -> 300000 | H16: =IF(H15="","",H15+H14) -> 410200.5 | M16: =IF(H16="","",SUM(M5:M14)) -> 1
A18: Benchmark 1.2 — chosen position
A19: Ticker chosen
A20: Case 1.2 asks about one position and requires the purchase date to be named. Write the full expected answer on the 'Answers' sheet.

Sheet Alloc-AssetClass
A1: Part 2 — Allocation by asset class
A2: All computed from the Positions sheet. Whichever pair D1 and D2 select is the answer benchmark case 1.1 must produce.
A4: Asset class | B4: Cost basis ($) | C4: % of invested | D4: % of total incl. cash | E4: Market value ($) | F4: % of invested | G4: % of total incl. cash
A5: Equity | B5: =SUMIFS(Positions!$F$5:$F$14,Positions!$B$5:$B$14,A5) -> 187500 | C5: =B5/Positions!$F$15 -> 0.65905097 | D5: =B5/Positions!$F$16 -> 0.625 | E5: =IF(Positions!$H$15="","",SUMIFS(Positions!$H$5:$H$14,Positions!$B$5:$B$14,A5)) -> 284713.5 | F5: =IF(E5="","",E5/Positions!$H$15) -> 0.72134061 | G5: =IF(E5="","",E5/Positions!$H$16) -> 0.69408375
A6: Fixed Income | B6: =SUMIFS(Positions!$F$5:$F$14,Positions!$B$5:$B$14,A6) -> 45000 | C6: =B6/Positions!$F$15 -> 0.15817223 | D6: =B6/Positions!$F$16 -> 0.15 | E6: =IF(Positions!$H$15="","",SUMIFS(Positions!$H$5:$H$14,Positions!$B$5:$B$14,A6)) -> 40975 | F6: =IF(E6="","",E6/Positions!$H$15) -> 0.10381289 | G6: =IF(E6="","",E6/Positions!$H$16) -> 0.099890176
A7: Real Estate | B7: =SUMIFS(Positions!$F$5:$F$14,Positions!$B$5:$B$14,A7) -> 27000 | C7: =B7/Positions!$F$15 -> 0.094903339 | D7: =B7/Positions!$F$16 -> 0.09 | E7: =IF(Positions!$H$15="","",SUMIFS(Positions!$H$5:$H$14,Positions!$B$5:$B$14,A7)) -> 28734 | F7: =IF(E7="","",E7/Positions!$H$15) -> 0.072799502 | G7: =IF(E7="","",E7/Positions!$H$16) -> 0.070048671
A8: Commodity | B8: =SUMIFS(Positions!$F$5:$F$14,Positions!$B$5:$B$14,A8) -> 25000 | C8: =B8/Positions!$F$15 -> 0.087873462 | D8: =B8/Positions!$F$16 -> 0.083333333 | E8: =IF(Positions!$H$15="","",SUMIFS(Positions!$H$5:$H$14,Positions!$B$5:$B$14,A8)) -> 40278 | F8: =IF(E8="","",E8/Positions!$H$15) -> 0.102047 | G8: =IF(E8="","",E8/Positions!$H$16) -> 0.098191007
A9: Cash | B9: =Positions!F14 -> 15500 | C9: n/a | D9: =B9/Positions!$F$16 -> 0.051666667 | E9: =Positions!H14 -> 15500 | F9: n/a | G9: =IF(Positions!$H$16="","",E9/Positions!$H$16) -> 0.0377864
A10: Total invested | B10: =SUM(B5:B8) -> 284500 | C10: =SUM(C5:C8) -> 1 | D10: =SUM(D5:D8) -> 0.94833333 | E10: =IF(Positions!$H$15="","",SUM(E5:E8)) -> 394700.5 | F10: =IF(E10="","",SUM(F5:F8)) -> 1 | G10: =IF(E10="","",SUM(G5:G8)) -> 0.9622136
A11: Total incl. cash | B11: =B10+B9 -> 300000 | D11: =D10+D9 -> 1 | E11: =IF(E10="","",E10+E9) -> 410200.5 | G11: =IF(E10="","",G10+G9) -> 1
A13: Tie-out check
A14: Cost basis vs Positions total | B14: =IF(ROUND(B10-Positions!F15,2)=0,"OK","MISMATCH") -> OK
A15: Market value vs Positions total | B15: =IF(E10="","(no prices yet)",IF(ROUND(E10-Positions!H15,2)=0,"OK","MISMATCH")) -> OK

Sheet Alloc-Sector
A1: Part 3 — Allocation by sector
A2: D3 decides whether the '(no sector)' row is reported explicitly or excluded from the denominator. Both denominators are shown so the difference is visible.
A4: Sector | B4: Cost basis ($) | C4: % of sectored | D4: % of invested | E4: Market value ($) | F4: % of sectored | G4: % of invested
A5: Technology | B5: =SUMIFS(Positions!$F$5:$F$13,Positions!$C$5:$C$13,A5) -> 80000 | C5: =B5/$B$10 -> 0.58181818 | D5: =B5/Positions!$F$15 -> 0.28119508 | E5: =IF(Positions!$H$15="","",SUMIFS(Positions!$H$5:$H$13,Positions!$C$5:$C$13,A5)) -> 114674 | F5: =IF(E5="","",E5/$E$10) -> 0.55079432 | G5: =IF(E5="","",E5/Positions!$H$15) -> 0.29053422
A6: Healthcare | B6: =SUMIFS(Positions!$F$5:$F$13,Positions!$C$5:$C$13,A6) -> 22500 | C6: =B6/$B$10 -> 0.16363636 | D6: =B6/Positions!$F$15 -> 0.079086116 | E6: =IF(Positions!$H$15="","",SUMIFS(Positions!$H$5:$H$13,Positions!$C$5:$C$13,A6)) -> 41281.5 | F6: =IF(E6="","",E6/$E$10) -> 0.19828048 | G6: =IF(E6="","",E6/Positions!$H$15) -> 0.10458943
A7: Financials | B7: =SUMIFS(Positions!$F$5:$F$13,Positions!$C$5:$C$13,A7) -> 20000 | C7: =B7/$B$10 -> 0.14545455 | D7: =B7/Positions!$F$15 -> 0.07029877 | E7: =IF(Positions!$H$15="","",SUMIFS(Positions!$H$5:$H$13,Positions!$C$5:$C$13,A7)) -> 35622 | F7: =IF(E7="","",E7/$E$10) -> 0.17109716 | G7: =IF(E7="","",E7/Positions!$H$15) -> 0.090250709
A8: Utilities | B8: =SUMIFS(Positions!$F$5:$F$13,Positions!$C$5:$C$13,A8) -> 15000 | C8: =B8/$B$10 -> 0.10909091 | D8: =B8/Positions!$F$15 -> 0.052724077 | E8: =IF(Positions!$H$15="","",SUMIFS(Positions!$H$5:$H$13,Positions!$C$5:$C$13,A8)) -> 16620 | F8: =IF(E8="","",E8/$E$10) -> 0.079828048 | G8: =IF(E8="","",E8/Positions!$H$15) -> 0.042107877
A9: (no sector) | B9: =SUMIFS(Positions!$F$5:$F$13,Positions!$C$5:$C$13,"(none)") -> 147000 | C9: n/a | D9: =B9/Positions!$F$15 -> 0.51669596 | E9: =IF(Positions!$H$15="","",SUMIFS(Positions!$H$5:$H$13,Positions!$C$5:$C$13,"(none)")) -> 186503 | F9: n/a | G9: =IF(E9="","",E9/Positions!$H$15) -> 0.47251777
A10: Sectored total | B10: =SUM(B5:B8) -> 137500 | C10: =SUM(C5:C8) -> 1 | E10: =IF(Positions!$H$15="","",SUM(E5:E8)) -> 208197.5 | F10: =IF(E10="","",SUM(F5:F8)) -> 1
A11: Invested total | B11: =B10+B9 -> 284500 | D11: =SUM(D5:D9) -> 1 | E11: =IF(E10="","",E10+E9) -> 394700.5 | G11: =IF(E10="","",SUM(G5:G9)) -> 1
A13: Benchmark 1.4 — expected answer for Technology
A14: Positions in Technology | B14: AAPL — 200 shares @ 324.96 = 64,992.00 (16.47% of invested) MSFT — 100 shares @ 496.82 = 49,682.00 (12.59% of invested) Technology total 114,674.00 — 29.05% of invested, 27.96% incl. cash, 55.08% of the sectored subset
A15: Does the answer have to flag the unsectored half? | B15: Yes. 47.25% of invested value (186,503.00 — SPY, TLT, GLD, VNQ) carries no sector. Reporting "Technology is 29%" without that leads the reader to assume the remaining 71% is distributed across other sectors, which is false — the other three sectors total only 23.7%. Under D3 the unsectored line is reported explicitly so the figures sum to 100%.

Sheet Volatility
A1: Part 4 — Twelve-month portfolio volatility
A2: Do NOT average the per-ticker volatilities: that ignores correlation and will be wrong. Do NOT use the covariance matrix the system produced: if it is wrong, both sides of the comparison inherit the same error.
A3: Method: build the portfolio's own return series. Mathematically equivalent to the covariance quadratic form and far easier here.
A5: Inputs
A6: Annualisation factor (D6) | B6: 252
A7: Std dev basis | B7: STDEV.S
A8: Weights source | B8: Market-value weights of invested (Positions col L)
A10: Weights (from Positions, market value)
A11: Ticker | B11: SPY | C11: AAPL | D11: MSFT | E11: JNJ | F11: JPM | G11: NEE | H11: TLT | I11: GLD | J11: VNQ | K11: Sum
A12: Weight | B12: =Positions!L5 -> 0.19385838 | C12: =Positions!L6 -> 0.16466156 | D12: =Positions!L7 -> 0.12587266 | E12: =Positions!L8 -> 0.10458943 | F12: =Positions!L9 -> 0.090250709 | G12: =Positions!L10 -> 0.042107877 | H12: =Positions!L11 -> 0.10381289 | I12: =Positions!L12 -> 0.102047 | J12: =Positions!L13 -> 0.072799502 | K12: =SUM(B12:J12) -> 1
A14: Daily closes — paste 12 months of adjusted closes below
A15: Paste dates in column A and closes in B:J, oldest first. Returns and the portfolio series compute automatically. Rows beyond your data stay blank.
A17: Date | B17: SPY | C17: AAPL | D17: MSFT | E17: JNJ | F17: JPM | G17: NEE | H17: TLT | I17: GLD | J17: VNQ | L17: Portfolio daily return | N17: SPY ret | O17: AAPL ret | P17: MSFT ret | Q17: JNJ ret | R17: JPM ret | S17: NEE ret | T17: TLT ret | U17: GLD ret | V17: VNQ ret
A18: 45903 | B18: 643.73999 | C18: 238.47 | D18: 505.35001 | E18: 178 | F18: 299.51001 | G18: 71.629997 | H18: 86.57 | I18: 328.14001 | J18: 90.760002
A19: 45904 | B19: 649.12 | C19: 239.78 | D19: 507.97 | E19: 178.75999 | F19: 303.82001 | G19: 70.870003 | H19: 87.230003 | I19: 326.69 | J19: 91.440002 | L19: =IF(COUNT(N19:V19)<9,"",SUMPRODUCT($B$12:$J$12,N19:V19)) -> 0.0053617666 | N19: =IF(OR(B19="",B18="",B18=0),"",B19/B18-1) -> 0.0083574191 | O19: =IF(OR(C19="",C18="",C18=0),"",C19/C18-1) -> 0.0054933432 | P19: =IF(OR(D19="",D18="",D18=0),"",D19/D18-1) -> 0.0051845159 | Q19: =IF(OR(E19="",E18="",E18=0),"",E19/E18-1) -> 0.0042696321 | R19: =IF(OR(F19="",F18="",F18=0),"",F19/F18-1) -> 0.014390162 | S19: =IF(OR(G19="",G18="",G18=0),"",G19/G18-1) -> -0.010610003 | T19: =IF(OR(H19="",H18="",H18=0),"",H19/H18-1) -> 0.0076239305 | U19: =IF(OR(I19="",I18="",I18=0),"",I19/I18-1) -> -0.0044188826 | V19: =IF(OR(J19="",J18="",J18=0),"",J19/J18-1) -> 0.0074922905
A20: 45905 | B20: 647.23999 | C20: 239.69 | D20: 495 | E20: 178.42999 | F20: 294.38 | G20: 70.900002 | H20: 88.559998 | I20: 331.04999 | J20: 92.470001 | L20: =IF(COUNT(N20:V20)<9,"",SUMPRODUCT($B$12:$J$12,N20:V20)) -> -0.003051832 | N20: =IF(OR(B20="",B19="",B19=0),"",B20/B19-1) -> -0.0028962363 | O20: =IF(OR(C20="",C19="",C19=0),"",C20/C19-1) -> -0.00037532879 | P20: =IF(OR(D20="",D19="",D19=0),"",D20/D19-1) -> -0.025533006 | Q20: =IF(OR(E20="",E19="",E19=0),"",E20/E19-1) -> -0.0018460609 | R20: =IF(OR(F20="",F19="",F19=0),"",F20/F19-1) -> -0.031071036 | S20: =IF(OR(G20="",G19="",G19=0),"",G20/G19-1) -> 0.00042329305 | T20: =IF(OR(H20="",H19="",H19=0),"",H20/H19-1) -> 0.015246981 | U20: =IF(OR(I20="",I19="",I19=0),"",I20/I19-1) -> 0.013345941 | V20: =IF(OR(J20="",J19="",J19=0),"",J20/J19-1) -> 0.011264203
A21: 45908 | B21: 648.83002 | C21: 237.88 | D21: 498.20001 | E21: 178.13 | F21: 292.91 | G21: 69.769997 | H21: 89.739998 | I21: 334.82001 | J21: 91.93 | L21: =IF(COUNT(N21:V21)<9,"",SUMPRODUCT($B$12:$J$12,N21:V21)) -> 0.00086912868 | N21: =IF(OR(B21="",B20="",B20=0),"",B21/B20-1) -> 0.0024566264 | O21: =IF(OR(C21="",C20="",C20=0),"",C21/C20-1) -> -0.0075514103 | P21: =IF(OR(D21="",D20="",D20=0),"",D21/D20-1) -> 0.0064646711 | Q21: =IF(OR(E21="",E20="",E20=0),"",E21/E20-1) -> -0.0016812633 | R21: =IF(OR(F21="",F20="",F20=0),"",F21/F20-1) -> -0.0049935498 | S21: =IF(OR(G21="",G20="",G20=0),"",G21/G20-1) -> -0.015938009 | T21: =IF(OR(H21="",H20="",H20=0),"",H21/H20-1) -> 0.013324304 | U21: =IF(OR(I21="",I20="",I20=0),"",I21/I20-1) -> 0.011388067 | V21: =IF(OR(J21="",J20="",J20=0),"",J21/J20-1) -> -0.0058397416
A22: 45909 | B22: 650.33002 | C22: 234.35001 | D22: 498.41 | E22: 176.96001 | F22: 297.85001 | G22: 70.07 | H22: 89.230003 | I22: 334.06 | J22: 91.720001 | L22: =IF(COUNT(N22:V22)<9,"",SUMPRODUCT($B$12:$J$12,N22:V22)) -> -0.001913966 | N22: =IF(OR(B22="",B21="",B21=0),"",B22/B21-1) -> 0.0023118536 | O22: =IF(OR(C22="",C21="",C21=0),"",C22/C21-1) -> -0.014839409 | P22: =IF(OR(D22="",D21="",D21=0),"",D22/D21-1) -> 0.0004215003 | Q22: =IF(OR(E22="",E21="",E21=0),"",E22/E21-1) -> -0.0065682262 | R22: =IF(OR(F22="",F21="",F21=0),"",F22/F21-1) -> 0.016865257 | S22: =IF(OR(G22="",G21="",G21=0),"",G22/G21-1) -> 0.0042998863 | T22: =IF(OR(H22="",H21="",H21=0),"",H22/H21-1) -> -0.0056830234 | U22: =IF(OR(I22="",I21="",I21=0),"",I22/I21-1) -> -0.0022699055 | V22: =IF(OR(J22="",J21="",J21=0),"",J22/J21-1) -> -0.0022843368
A23: 45910 | B23: 652.21002 | C23: 226.78999 | D23: 500.37 | E23: 175.78999 | F23: 300.54001 | G23: 71.040001 | H23: 89.739998 | I23: 335.26001 | J23: 91.57 | L23: =IF(COUNT(N23:V23)<9,"",SUMPRODUCT($B$12:$J$12,N23:V23)) -> -0.0027091477 | N23: =IF(OR(B23="",B22="",B22=0),"",B23/B22-1) -> 0.0028908475 | O23: =IF(OR(C23="",C22="",C22=0),"",C23/C22-1) -> -0.032259495 | P23: =IF(OR(D23="",D22="",D22=0),"",D23/D22-1) -> 0.0039324882 | Q23: =IF(OR(E23="",E22="",E22=0),"",E23/E22-1) -> -0.0066117393 | R23: =IF(OR(F23="",F22="",F22=0),"",F23/F22-1) -> 0.0090313997 | S23: =IF(OR(G23="",G22="",G22=0),"",G23/G22-1) -> 0.013843317 | T23: =IF(OR(H23="",H22="",H22=0),"",H23/H22-1) -> 0.0057155047 | U23: =IF(OR(I23="",I22="",I22=0),"",I23/I22-1) -> 0.0035922056 | V23: =IF(OR(J23="",J22="",J22=0),"",J23/J22-1) -> -0.0016354287
A24: 45911 | B24: 657.63 | C24: 230.03 | D24: 501.01001 | E24: 178.5 | F24: 305.56 | G24: 71.32 | H24: 90.339996 | I24: 334.76001 | J24: 93.239998 | L24: =IF(COUNT(N24:V24)<9,"",SUMPRODUCT($B$12:$J$12,N24:V24)) -> 0.009279798 | N24: =IF(OR(B24="",B23="",B23=0),"",B24/B23-1) -> 0.0083101804 | O24: =IF(OR(C24="",C23="",C23=0),"",C24/C23-1) -> 0.014286369 | P24: =IF(OR(D24="",D23="",D23=0),"",D24/D23-1) -> 0.0012790828 | Q24: =IF(OR(E24="",E23="",E23=0),"",E24/E23-1) -> 0.01541616 | R24: =IF(OR(F24="",F23="",F23=0),"",F24/F23-1) -> 0.01670323 | S24: =IF(OR(G24="",G23="",G23=0),"",G24/G23-1) -> 0.0039414242 | T24: =IF(OR(H24="",H23="",H23=0),"",H24/H23-1) -> 0.0066859649 | U24: =IF(OR(I24="",I23="",I23=0),"",I24/I23-1) -> -0.0014913798 | V24: =IF(OR(J24="",J23="",J23=0),"",J24/J23-1) -> 0.018237394
A25: 45912 | B25: 657.40997 | C25: 234.07001 | D25: 509.89999 | E25: 178.06 | F25: 306.91 | G25: 71.639999 | H25: 89.949997 | I25: 335.42001 | J25: 92.809998 | L25: =IF(COUNT(N25:V25)<9,"",SUMPRODUCT($B$12:$J$12,N25:V25)) -> 0.0048077381 | N25: =IF(OR(B25="",B24="",B24=0),"",B25/B24-1) -> -0.00033458288 | O25: =IF(OR(C25="",C24="",C24=0),"",C25/C24-1) -> 0.017562964 | P25: =IF(OR(D25="",D24="",D24=0),"",D25/D24-1) -> 0.017744125 | Q25: =IF(OR(E25="",E24="",E24=0),"",E25/E24-1) -> -0.0024649997 | R25: =IF(OR(F25="",F24="",F24=0),"",F25/F24-1) -> 0.0044181376 | S25: =IF(OR(G25="",G24="",G24=0),"",G25/G24-1) -> 0.0044868157 | T25: =IF(OR(H25="",H24="",H24=0),"",H25/H24-1) -> -0.004317018 | U25: =IF(OR(I25="",I24="",I24=0),"",I25/I24-1) -> 0.0019715726 | V25: =IF(OR(J25="",J24="",J24=0),"",J25/J24-1) -> -0.004611758
A26: 45915 | B26: 660.90997 | C26: 236.7 | D26: 515.35999 | E26: 177.39999 | F26: 308.89999 | G26: 71.5 | H26: 90.160004 | I26: 338.91 | J26: 92.660004 | L26: =IF(COUNT(N26:V26)<9,"",SUMPRODUCT($B$12:$J$12,N26:V26)) -> 0.0055317691 | N26: =IF(OR(B26="",B25="",B25=0),"",B26/B25-1) -> 0.0053239229 | O26: =IF(OR(C26="",C25="",C25=0),"",C26/C25-1) -> 0.01123591 | P26: =IF(OR(D26="",D25="",D25=0),"",D26/D25-1) -> 0.010707965 | Q26: =IF(OR(E26="",E25="",E25=0),"",E26/E25-1) -> -0.0037066364 | R26: =IF(OR(F26="",F25="",F25=0),"",F26/F25-1) -> 0.0064839536 | S26: =IF(OR(G26="",G25="",G25=0),"",G26/G25-1) -> -0.001954207 | T26: =IF(OR(H26="",H25="",H25=0),"",H26/H25-1) -> 0.0023347051 | U26: =IF(OR(I26="",I25="",I25=0),"",I26/I25-1) -> 0.010404836 | V26: =IF(OR(J26="",J25="",J25=0),"",J26/J25-1) -> -0.0016161394
A27: 45916 | B27: 660 | C27: 238.14999 | D27: 509.04001 | E27: 176.46001 | F27: 309.19 | G27: 69.830002 | H27: 90.349998 | I27: 339.59 | J27: 92.169998 | L27: =IF(COUNT(N27:V27)<9,"",SUMPRODUCT($B$12:$J$12,N27:V27)) -> -0.0022162392 | N27: =IF(OR(B27="",B26="",B26=0),"",B27/B26-1) -> -0.0013768489 | O27: =IF(OR(C27="",C26="",C26=0),"",C27/C26-1) -> 0.0061258849 | P27: =IF(OR(D27="",D26="",D26=0),"",D27/D26-1) -> -0.012263228 | Q27: =IF(OR(E27="",E26="",E26=0),"",E27/E26-1) -> -0.0052986878 | R27: =IF(OR(F27="",F26="",F26=0),"",F27/F26-1) -> 0.00093884283 | S27: =IF(OR(G27="",G26="",G26=0),"",G27/G26-1) -> -0.023356618 | T27: =IF(OR(H27="",H26="",H26=0),"",H27/H26-1) -> 0.0021073071 | U27: =IF(OR(I27="",I26="",I26=0),"",I27/I26-1) -> 0.0020064108 | V27: =IF(OR(J27="",J26="",J26=0),"",J27/J26-1) -> -0.0052882093
A28: 45917 | B28: 659.17999 | C28: 238.99001 | D28: 510.01999 | E28: 177.2 | F28: 311.75 | G28: 70.309998 | H28: 90.120003 | I28: 336.97 | J28: 92.050003 | L28: =IF(COUNT(N28:V28)<9,"",SUMPRODUCT($B$12:$J$12,N28:V28)) -> 0.00091120112 | N28: =IF(OR(B28="",B27="",B27=0),"",B28/B27-1) -> -0.0012424353 | O28: =IF(OR(C28="",C27="",C27=0),"",C28/C27-1) -> 0.0035272375 | P28: =IF(OR(D28="",D27="",D27=0),"",D28/D27-1) -> 0.0019251541 | Q28: =IF(OR(E28="",E27="",E27=0),"",E28/E27-1) -> 0.0041935294 | R28: =IF(OR(F28="",F27="",F27=0),"",F28/F27-1) -> 0.0082796906 | S28: =IF(OR(G28="",G27="",G27=0),"",G28/G27-1) -> 0.0068737751 | T28: =IF(OR(H28="",H27="",H27=0),"",H28/H27-1) -> -0.0025456085 | U28: =IF(OR(I28="",I27="",I27=0),"",I28/I27-1) -> -0.0077151717 | V28: =IF(OR(J28="",J27="",J27=0),"",J28/J27-1) -> -0.0013018891
A29: 45918 | B29: 662.26001 | C29: 237.88 | D29: 508.45001 | E29: 174.16 | F29: 313.23001 | G29: 70.790001 | H29: 89.190002 | I29: 335.62 | J29: 92.25 | L29: =IF(COUNT(N29:V29)<9,"",SUMPRODUCT($B$12:$J$12,N29:V29)) -> -0.00264679 | N29: =IF(OR(B29="",B28="",B28=0),"",B29/B28-1) -> 0.0046724978 | O29: =IF(OR(C29="",C28="",C28=0),"",C29/C28-1) -> -0.0046445482 | P29: =IF(OR(D29="",D28="",D28=0),"",D29/D28-1) -> -0.0030782652 | Q29: =IF(OR(E29="",E28="",E28=0),"",E29/E28-1) -> -0.017155719 | R29: =IF(OR(F29="",F28="",F28=0),"",F29/F28-1) -> 0.004747429 | S29: =IF(OR(G29="",G28="",G28=0),"",G29/G28-1) -> 0.0068269574 | T29: =IF(OR(H29="",H28="",H28=0),"",H29/H28-1) -> -0.010319577 | U29: =IF(OR(I29="",I28="",I28=0),"",I29/I28-1) -> -0.0040063095 | V29: =IF(OR(J29="",J28="",J28=0),"",J29/J28-1) -> 0.002172699
A30: 45919 | B30: 663.70001 | C30: 245.5 | D30: 517.92999 | E30: 176.19 | F30: 314.78 | G30: 71.080002 | H30: 89.019997 | I30: 339.17999 | J30: 91.650002 | L30: =IF(COUNT(N30:V30)<9,"",SUMPRODUCT($B$12:$J$12,N30:V30)) -> 0.010292244 | N30: =IF(OR(B30="",B29="",B29=0),"",B30/B29-1) -> 0.0021743763 | O30: =IF(OR(C30="",C29="",C29=0),"",C30/C29-1) -> 0.032032937 | P30: =IF(OR(D30="",D29="",D29=0),"",D30/D29-1) -> 0.018644862 | Q30: =IF(OR(E30="",E29="",E29=0),"",E30/E29-1) -> 0.011655941 | R30: =IF(OR(F30="",F29="",F29=0),"",F30/F29-1) -> 0.0049484013 | S30: =IF(OR(G30="",G29="",G29=0),"",G30/G29-1) -> 0.0040966367 | T30: =IF(OR(H30="",H29="",H29=0),"",H30/H29-1) -> -0.0019061082 | U30: =IF(OR(I30="",I29="",I29=0),"",I30/I29-1) -> 0.010607227 | V30: =IF(OR(J30="",J29="",J29=0),"",J30/J29-1) -> -0.0065040485
... A269: 46267 | B269: 765.15997 | C269: 324.95999 | D269: 496.82001 | E269: 275.20999 | F269: 356.22 | G269: 83.099998 | H269: 81.949997 | I269: 402.78 | J269: 95.779999 | L269: =IF(COUNT(N269:V269)<9,"",SUMPRODUCT($B$12:$J$12,N269:V269)) -> 0.0029377545 | N269: =IF(OR(B269="",B268="",B268=0),"",B269/B268-1) -> 0.0044369027 | O269: =IF(OR(C269="",C268="",C268=0),"",C269/C268-1) -> -0.00052290907 | P269: =IF(OR(D269="",D268="",D268=0),"",D269/D268-1) -> -0.0083828625 | Q269: =IF(OR(E269="",E268="",E268=0),"",E269/E268-1) -> 0.014823515 | R269: =IF(OR(F269="",F268="",F268=0),"",F269/F268-1) -> 0.0035779377 | S269: =IF(OR(G269="",G268="",G268=0),"",G269/G268-1) -> 0.0020498995 | T269: =IF(OR(H269="",H268="",H268=0),"",H269/H268-1) -> 0.00097708805 | U269: =IF(OR(I269="",I268="",I268=0),"",I269/I268-1) -> 0.015198485 | V269: =IF(OR(J269="",J268="",J268=0),"",J269/J268-1) -> -0.0053998365
L270: =IF(COUNT(N270:V270)<9,"",SUMPRODUCT($B$12:$J$12,N270:V270)) | N270: =IF(OR(B270="",B269="",B269=0),"",B270/B269-1) | O270: =IF(OR(C270="",C269="",C269=0),"",C270/C269-1) | P270: =IF(OR(D270="",D269="",D269=0),"",D270/D269-1) | Q270: =IF(OR(E270="",E269="",E269=0),"",E270/E269-1) | R270: =IF(OR(F270="",F269="",F269=0),"",F270/F269-1) | S270: =IF(OR(G270="",G269="",G269=0),"",G270/G269-1) | T270: =IF(OR(H270="",H269="",H269=0),"",H270/H269-1) | U270: =IF(OR(I270="",I269="",I269=0),"",I270/I269-1) | V270: =IF(OR(J270="",J269="",J269=0),"",J270/J269-1)
L271: =IF(COUNT(N271:V271)<9,"",SUMPRODUCT($B$12:$J$12,N271:V271)) | N271: =IF(OR(B271="",B270="",B270=0),"",B271/B270-1) | O271: =IF(OR(C271="",C270="",C270=0),"",C271/C270-1) | P271: =IF(OR(D271="",D270="",D270=0),"",D271/D270-1) | Q271: =IF(OR(E271="",E270="",E270=0),"",E271/E270-1) | R271: =IF(OR(F271="",F270="",F270=0),"",F271/F270-1) | S271: =IF(OR(G271="",G270="",G270=0),"",G271/G270-1) | T271: =IF(OR(H271="",H270="",H270=0),"",H271/H270-1) | U271: =IF(OR(I271="",I270="",I270=0),"",I271/I270-1) | V271: =IF(OR(J271="",J270="",J270=0),"",J271/J270-1)
L272: =IF(COUNT(N272:V272)<9,"",SUMPRODUCT($B$12:$J$12,N272:V272)) | N272: =IF(OR(B272="",B271="",B271=0),"",B272/B271-1) | O272: =IF(OR(C272="",C271="",C271=0),"",C272/C271-1) | P272: =IF(OR(D272="",D271="",D271=0),"",D272/D271-1) | Q272: =IF(OR(E272="",E271="",E271=0),"",E272/E271-1) | R272: =IF(OR(F272="",F271="",F271=0),"",F272/F271-1) | S272: =IF(OR(G272="",G271="",G271=0),"",G272/G271-1) | T272: =IF(OR(H272="",H271="",H271=0),"",H272/H271-1) | U272: =IF(OR(I272="",I271="",I271=0),"",I272/I271-1) | V272: =IF(OR(J272="",J271="",J271=0),"",J272/J271-1)
L273: =IF(COUNT(N273:V273)<9,"",SUMPRODUCT($B$12:$J$12,N273:V273)) | N273: =IF(OR(B273="",B272="",B272=0),"",B273/B272-1) | O273: =IF(OR(C273="",C272="",C272=0),"",C273/C272-1) | P273: =IF(OR(D273="",D272="",D272=0),"",D273/D272-1) | Q273: =IF(OR(E273="",E272="",E272=0),"",E273/E272-1) | R273: =IF(OR(F273="",F272="",F272=0),"",F273/F272-1) | S273: =IF(OR(G273="",G272="",G272=0),"",G273/G272-1) | T273: =IF(OR(H273="",H272="",H272=0),"",H273/H272-1) | U273: =IF(OR(I273="",I272="",I272=0),"",I273/I272-1) | V273: =IF(OR(J273="",J272="",J272=0),"",J273/J272-1)
L274: =IF(COUNT(N274:V274)<9,"",SUMPRODUCT($B$12:$J$12,N274:V274)) | N274: =IF(OR(B274="",B273="",B273=0),"",B274/B273-1) | O274: =IF(OR(C274="",C273="",C273=0),"",C274/C273-1) | P274: =IF(OR(D274="",D273="",D273=0),"",D274/D273-1) | Q274: =IF(OR(E274="",E273="",E273=0),"",E274/E273-1) | R274: =IF(OR(F274="",F273="",F273=0),"",F274/F273-1) | S274: =IF(OR(G274="",G273="",G273=0),"",G274/G273-1) | T274: =IF(OR(H274="",H273="",H273=0),"",H274/H273-1) | U274: =IF(OR(I274="",I273="",I273=0),"",I274/I273-1) | V274: =IF(OR(J274="",J273="",J273=0),"",J274/J273-1)
L275: =IF(COUNT(N275:V275)<9,"",SUMPRODUCT($B$12:$J$12,N275:V275)) | N275: =IF(OR(B275="",B274="",B274=0),"",B275/B274-1) | O275: =IF(OR(C275="",C274="",C274=0),"",C275/C274-1) | P275: =IF(OR(D275="",D274="",D274=0),"",D275/D274-1) | Q275: =IF(OR(E275="",E274="",E274=0),"",E275/E274-1) | R275: =IF(OR(F275="",F274="",F274=0),"",F275/F274-1) | S275: =IF(OR(G275="",G274="",G274=0),"",G275/G274-1) | T275: =IF(OR(H275="",H274="",H274=0),"",H275/H274-1) | U275: =IF(OR(I275="",I274="",I274=0),"",I275/I274-1) | V275: =IF(OR(J275="",J274="",J274=0),"",J275/J274-1)
L276: =IF(COUNT(N276:V276)<9,"",SUMPRODUCT($B$12:$J$12,N276:V276)) | N276: =IF(OR(B276="",B275="",B275=0),"",B276/B275-1) | O276: =IF(OR(C276="",C275="",C275=0),"",C276/C275-1) | P276: =IF(OR(D276="",D275="",D275=0),"",D276/D275-1) | Q276: =IF(OR(E276="",E275="",E275=0),"",E276/E275-1) | R276: =IF(OR(F276="",F275="",F275=0),"",F276/F275-1) | S276: =IF(OR(G276="",G275="",G275=0),"",G276/G275-1) | T276: =IF(OR(H276="",H275="",H275=0),"",H276/H275-1) | U276: =IF(OR(I276="",I275="",I275=0),"",I276/I275-1) | V276: =IF(OR(J276="",J275="",J275=0),"",J276/J275-1)
L277: =IF(COUNT(N277:V277)<9,"",SUMPRODUCT($B$12:$J$12,N277:V277)) | N277: =IF(OR(B277="",B276="",B276=0),"",B277/B276-1) | O277: =IF(OR(C277="",C276="",C276=0),"",C277/C276-1) | P277: =IF(OR(D277="",D276="",D276=0),"",D277/D276-1) | Q277: =IF(OR(E277="",E276="",E276=0),"",E277/E276-1) | R277: =IF(OR(F277="",F276="",F276=0),"",F277/F276-1) | S277: =IF(OR(G277="",G276="",G276=0),"",G277/G276-1) | T277: =IF(OR(H277="",H276="",H276=0),"",H277/H276-1) | U277: =IF(OR(I277="",I276="",I276=0),"",I277/I276-1) | V277: =IF(OR(J277="",J276="",J276=0),"",J277/J276-1)
L278: =IF(COUNT(N278:V278)<9,"",SUMPRODUCT($B$12:$J$12,N278:V278)) | N278: =IF(OR(B278="",B277="",B277=0),"",B278/B277-1) | O278: =IF(OR(C278="",C277="",C277=0),"",C278/C277-1) | P278: =IF(OR(D278="",D277="",D277=0),"",D278/D277-1) | Q278: =IF(OR(E278="",E277="",E277=0),"",E278/E277-1) | R278: =IF(OR(F278="",F277="",F277=0),"",F278/F277-1) | S278: =IF(OR(G278="",G277="",G277=0),"",G278/G277-1) | T278: =IF(OR(H278="",H277="",H277=0),"",H278/H277-1) | U278: =IF(OR(I278="",I277="",I277=0),"",I278/I277-1) | V278: =IF(OR(J278="",J277="",J277=0),"",J278/J277-1)
L279: =IF(COUNT(N279:V279)<9,"",SUMPRODUCT($B$12:$J$12,N279:V279)) | N279: =IF(OR(B279="",B278="",B278=0),"",B279/B278-1) | O279: =IF(OR(C279="",C278="",C278=0),"",C279/C278-1) | P279: =IF(OR(D279="",D278="",D278=0),"",D279/D278-1) | Q279: =IF(OR(E279="",E278="",E278=0),"",E279/E278-1) | R279: =IF(OR(F279="",F278="",F278=0),"",F279/F278-1) | S279: =IF(OR(G279="",G278="",G278=0),"",G279/G278-1) | T279: =IF(OR(H279="",H278="",H278=0),"",H279/H278-1) | U279: =IF(OR(I279="",I278="",I278=0),"",I279/I278-1) | V279: =IF(OR(J279="",J278="",J278=0),"",J279/J278-1)
L280: =IF(COUNT(N280:V280)<9,"",SUMPRODUCT($B$12:$J$12,N280:V280)) | N280: =IF(OR(B280="",B279="",B279=0),"",B280/B279-1) | O280: =IF(OR(C280="",C279="",C279=0),"",C280/C279-1) | P280: =IF(OR(D280="",D279="",D279=0),"",D280/D279-1) | Q280: =IF(OR(E280="",E279="",E279=0),"",E280/E279-1) | R280: =IF(OR(F280="",F279="",F279=0),"",F280/F279-1) | S280: =IF(OR(G280="",G279="",G279=0),"",G280/G279-1) | T280: =IF(OR(H280="",H279="",H279=0),"",H280/H279-1) | U280: =IF(OR(I280="",I279="",I279=0),"",I280/I279-1) | V280: =IF(OR(J280="",J279="",J279=0),"",J280/J279-1)
L281: =IF(COUNT(N281:V281)<9,"",SUMPRODUCT($B$12:$J$12,N281:V281)) | N281: =IF(OR(B281="",B280="",B280=0),"",B281/B280-1) | O281: =IF(OR(C281="",C280="",C280=0),"",C281/C280-1) | P281: =IF(OR(D281="",D280="",D280=0),"",D281/D280-1) | Q281: =IF(OR(E281="",E280="",E280=0),"",E281/E280-1) | R281: =IF(OR(F281="",F280="",F280=0),"",F281/F280-1) | S281: =IF(OR(G281="",G280="",G280=0),"",G281/G280-1) | T281: =IF(OR(H281="",H280="",H280=0),"",H281/H280-1) | U281: =IF(OR(I281="",I280="",I280=0),"",I281/I280-1) | V281: =IF(OR(J281="",J280="",J280=0),"",J281/J280-1)
... L287: =IF(COUNT(N287:V287)<9,"",SUMPRODUCT($B$12:$J$12,N287:V287)) | N287: =IF(OR(B287="",B286="",B286=0),"",B287/B286-1) | O287: =IF(OR(C287="",C286="",C286=0),"",C287/C286-1) | P287: =IF(OR(D287="",D286="",D286=0),"",D287/D286-1) | Q287: =IF(OR(E287="",E286="",E286=0),"",E287/E286-1) | R287: =IF(OR(F287="",F286="",F286=0),"",F287/F286-1) | S287: =IF(OR(G287="",G286="",G286=0),"",G287/G286-1) | T287: =IF(OR(H287="",H286="",H286=0),"",H287/H286-1) | U287: =IF(OR(I287="",I286="",I286=0),"",I287/I286-1) | V287: =IF(OR(J287="",J286="",J286=0),"",J287/J286-1)
...

Sheet Answers
A1: Part 5 — Expected answers, written out
A2: In the shape benchmark.md Part 3b requires: the result in the units asked for, the data age as an as-of date, the source for any policy claim, and what it did not do.
A4: Case | B4: Prompt | C4: Expected answer (write out in full)
A5: 1.1 | B5: What is my current allocation by asset class? | C5: Your portfolio is 410,200.50 as of the 2026-09-02 close, allocated by market value as: Equity 284,713.50 69.41% Fixed Income 40,975.00 9.99% Commodity 40,278.00 9.82% Real Estate 28,734.00 7.00% Cash 15,500.00 3.78% Prices are the 2026-09-02 settled close, the most recent available. Percentages are of total portfolio value including the cash balance (D1: market value; D2: cash included). Excluding cash, Equity is 72.13% of the 394,700.50 invested. Not done: asset class comes from the assets table, not a live classification service. No look-through — SPY, TLT, GLD and VNQ are counted at fund level, so this describes what you hold, not the underlying economic exposure.
A6: 1.2 | B6: How has position X performed since purchase? | C6: JPM is up 15,622.00, or 78.11%, since you bought it on 2024-07-15. Purchased 100 shares at an average 200.00 = 20,000.00 on 2024-07-15 Now 100 shares at 356.22 = 35,622.00 Gain +15,622.00 (+78.11%) Price as of the 2026-09-02 settled close. Cost basis is the average_price recorded on the holding. Not done: this is price return only, not total return (D4). JPM pays a dividend and none of it is counted here, because dividends are stored without a portfolio_id and cannot be attributed to a holding. Actual return is higher by an amount this system cannot currently compute. Nor does it account for a position built in tranches — one purchase date and one average price are all the holding records.
A7: 1.3 | B7: What is my volatility over twelve months? | C7: Your portfolio's annualised volatility over the past twelve months is 10.29%. Method standard deviation of the portfolio's own daily returns Weights market value of invested assets at the 2026-09-02 close, cash excluded Window 2025-09-03 to 2026-09-02, 251 daily returns from 252 closes Statistic sample standard deviation, 0.00648436 daily Annualised x SQRT(252) This is portfolio volatility, not an average of the individual holdings. Those average 20.54% weighted; the portfolio is far below that because the holdings are imperfectly correlated — TLT at 9.55% and GLD at 29.21% move largely independently of the equity block. Not done: cash is excluded from the weights. Including it, since cash has no volatility, gives 9.90% against total portfolio value. Twelve months of daily data is one estimate from one window and says nothing about volatility in a different regime.
A8: 1.4 | B8: What positions do I hold in sector Y? | C8: You hold 2 positions in Technology, worth 114,674.00, 29.05% of invested assets. AAPL 200 shares at 324.96 64,992.00 16.47% MSFT 100 shares at 496.82 49,682.00 12.59% Prices as of the 2026-09-02 settled close. Percentages are of invested market value (394,700.50); against total portfolio value including cash the figure is 27.96%. Important: 47.25% of invested value (186,503.00 — SPY, TLT, GLD and VNQ) carries no sector classification at all. Technology is 55.08% of the classified portion. The other classified sectors are Healthcare 10.46%, Financials 9.03% and Utilities 4.21% of invested. Not done: no look-through into fund constituents. SPY holds a substantial technology weight that is not counted here, so true technology exposure is materially higher than 29.05%. Sector data comes from the assets table.
A10: Part 6 — What these values do not cover
A11: Price return only, not total return | C11: Dividends live in a table with no portfolio_id, so no dividend can be attributed to a portfolio. Any P&L here understates actual return on the dividend-paying positions (JNJ, JPM, NEE, VNQ and TLT in particular).
A12: Single purchase date per position | C12: PortfolioHolding carries one purchase_date and one average_price, which cannot represent a position built in tranches. Fine for this synthetic portfolio, where each position was a single purchase. Not fine for a real portfolio with savings plans or DRIP.
A13: Single currency | C13: Everything here is USD. There is no FX conversion anywhere in the codebase, so these values say nothing about whether a multi-currency portfolio would compute correctly.
A14: No look-through | C14: SPY, TLT, GLD and VNQ are treated as having no sector. A real sector allocation would decompose SPY into its constituents. Out of scope, but it means the sector figures describe the holdings, not the underlying economic exposure.

Sheet Compliance
A1: Part 7 — Compliance against docs/IPS.md
A2: Every share is market value / total portfolio value incl. cash (Positions!H16), per D1 and D2 and per the IPS header. Limits are typed in from docs/IPS.md (blue). Everything else links or computes.
A3: D9: a figure exactly at a limit passes. "No more than 12%" admits 12.00%; "no less than 3%" admits 3.00%. Status formulas use strict > and <. Do not round before comparing — MSFT and JNJ are the rows that catch a checker that does.
A4: Distance to limit is signed so that positive = breach, negative = headroom. In dollars: market value − limit × total (max bound) or limit × total − market value (min bound). As a fraction: dollars / total.
A6: Limits from docs/IPS.md
A7: Clause | B7: What | C7: Bound | D7: Limit | E7: Source
A8: IPS-3.1 | B8: Equity | C8: min | D8: 0.4 | E8: docs/IPS.md
A9: IPS-3.1 | B9: Equity | C9: max | D9: 0.65 | E9: docs/IPS.md
A10: IPS-3.2 | B10: Fixed Income | C10: min | D10: 0.08 | E10: docs/IPS.md
A11: IPS-3.2 | B11: Fixed Income | C11: max | D11: 0.3 | E11: docs/IPS.md
A12: IPS-3.3 | B12: Commodity | C12: max | D12: 0.15 | E12: docs/IPS.md
A13: IPS-3.4 | B13: Real Estate | C13: max | D13: 0.15 | E13: docs/IPS.md
A14: IPS-3.5 | B14: Cash | C14: min | D14: 0.03 | E14: docs/IPS.md
A15: IPS-4.1 | B15: Single instrument | C15: max | D15: 0.12 | E15: docs/IPS.md
A16: IPS-4.2 | B16: Single issuer (direct shares) | C16: max | D16: 0.1 | E16: docs/IPS.md
A17: IPS-4.3 | B17: Single sector (direct shares) | C17: max | D17: 0.25 | E17: docs/IPS.md
A18: Total portfolio value | D18: =Positions!$H$16 -> 410200.5 | E18: Positions!H16 — the one denominator
A20: Section 3 — Strategic allocation (asset-class bands)
A21: Market values from Alloc-AssetClass column E. Both bounds of a band are separate rows; a band is breached if either row is.
A22: Clause | B22: Subject | C22: Market value ($) | D22: Share of total | E22: Bound | F22: Limit | G22: Status | H22: Distance ($) | I22: Distance (fraction)
A23: IPS-3.1 | B23: Equity | C23: ='Alloc-AssetClass'!E5 -> 284713.5 | D23: =IF(C23="","",C23/$D$18) -> 0.69408375 | E23: min | F23: =$D$8 -> 0.4 | G23: =IF(D23="","",IF(D23<F23,"breach","ok")) -> ok | H23: =IF(C23="","",F23*$D$18-C23) -> -120633.3 | I23: =IF(H23="","",H23/$D$18) -> -0.29408375
A24: IPS-3.1 | B24: Equity | C24: ='Alloc-AssetClass'!E5 -> 284713.5 | D24: =IF(C24="","",C24/$D$18) -> 0.69408375 | E24: max | F24: =$D$9 -> 0.65 | G24: =IF(D24="","",IF(D24>F24,"breach","ok")) -> breach | H24: =IF(C24="","",C24-F24*$D$18) -> 18083.175 | I24: =IF(H24="","",H24/$D$18) -> 0.044083747
A25: IPS-3.2 | B25: Fixed Income | C25: ='Alloc-AssetClass'!E6 -> 40975 | D25: =IF(C25="","",C25/$D$18) -> 0.099890176 | E25: min | F25: =$D$10 -> 0.08 | G25: =IF(D25="","",IF(D25<F25,"breach","ok")) -> ok | H25: =IF(C25="","",F25*$D$18-C25) -> -8158.96 | I25: =IF(H25="","",H25/$D$18) -> -0.019890176
A26: IPS-3.2 | B26: Fixed Income | C26: ='Alloc-AssetClass'!E6 -> 40975 | D26: =IF(C26="","",C26/$D$18) -> 0.099890176 | E26: max | F26: =$D$11 -> 0.3 | G26: =IF(D26="","",IF(D26>F26,"breach","ok")) -> ok | H26: =IF(C26="","",C26-F26*$D$18) -> -82085.15 | I26: =IF(H26="","",H26/$D$18) -> -0.20010982
A27: IPS-3.3 | B27: Commodity | C27: ='Alloc-AssetClass'!E8 -> 40278 | D27: =IF(C27="","",C27/$D$18) -> 0.098191007 | E27: max | F27: =$D$12 -> 0.15 | G27: =IF(D27="","",IF(D27>F27,"breach","ok")) -> ok | H27: =IF(C27="","",C27-F27*$D$18) -> -21252.075 | I27: =IF(H27="","",H27/$D$18) -> -0.051808993
A28: IPS-3.4 | B28: Real Estate | C28: ='Alloc-AssetClass'!E7 -> 28734 | D28: =IF(C28="","",C28/$D$18) -> 0.070048671 | E28: max | F28: =$D$13 -> 0.15 | G28: =IF(D28="","",IF(D28>F28,"breach","ok")) -> ok | H28: =IF(C28="","",C28-F28*$D$18) -> -32796.075 | I28: =IF(H28="","",H28/$D$18) -> -0.079951329
A29: IPS-3.5 | B29: Cash | C29: ='Alloc-AssetClass'!E9 -> 15500 | D29: =IF(C29="","",C29/$D$18) -> 0.0377864 | E29: min | F29: =$D$14 -> 0.03 | G29: =IF(D29="","",IF(D29<F29,"breach","ok")) -> ok | H29: =IF(C29="","",F29*$D$18-C29) -> -3193.985 | I29: =IF(H29="","",H29/$D$18) -> -0.0077863996
A31: IPS-4.1 — Single instrument, every holding, funds included
A32: Market values from Positions column H.
A33: Clause | B33: Subject | C33: Market value ($) | D33: Share of total | E33: Bound | F33: Limit | G33: Status | H33: Distance ($) | I33: Distance (fraction)
A34: IPS-4.1 | B34: SPY | C34: =Positions!H5 -> 76516 | D34: =IF(C34="","",C34/$D$18) -> 0.18653317 | E34: max | F34: =$D$15 -> 0.12 | G34: =IF(D34="","",IF(D34>F34,"breach","ok")) -> breach | H34: =IF(C34="","",C34-F34*$D$18) -> 27291.94 | I34: =IF(H34="","",H34/$D$18) -> 0.066533171
A35: IPS-4.1 | B35: AAPL | C35: =Positions!H6 -> 64992 | D35: =IF(C35="","",C35/$D$18) -> 0.15843959 | E35: max | F35: =$D$15 -> 0.12 | G35: =IF(D35="","",IF(D35>F35,"breach","ok")) -> breach | H35: =IF(C35="","",C35-F35*$D$18) -> 15767.94 | I35: =IF(H35="","",H35/$D$18) -> 0.038439592
A36: IPS-4.1 | B36: MSFT | C36: =Positions!H7 -> 49682 | D36: =IF(C36="","",C36/$D$18) -> 0.12111638 | E36: max | F36: =$D$15 -> 0.12 | G36: =IF(D36="","",IF(D36>F36,"breach","ok")) -> breach | H36: =IF(C36="","",C36-F36*$D$18) -> 457.94 | I36: =IF(H36="","",H36/$D$18) -> 0.0011163809
A37: IPS-4.1 | B37: JNJ | C37: =Positions!H8 -> 41281.5 | D37: =IF(C37="","",C37/$D$18) -> 0.10063737 | E37: max | F37: =$D$15 -> 0.12 | G37: =IF(D37="","",IF(D37>F37,"breach","ok")) -> ok | H37: =IF(C37="","",C37-F37*$D$18) -> -7942.56 | I37: =IF(H37="","",H37/$D$18) -> -0.019362629
A38: IPS-4.1 | B38: JPM | C38: =Positions!H9 -> 35622 | D38: =IF(C38="","",C38/$D$18) -> 0.08684046 | E38: max | F38: =$D$15 -> 0.12 | G38: =IF(D38="","",IF(D38>F38,"breach","ok")) -> ok | H38: =IF(C38="","",C38-F38*$D$18) -> -13602.06 | I38: =IF(H38="","",H38/$D$18) -> -0.03315954
A39: IPS-4.1 | B39: NEE | C39: =Positions!H10 -> 16620 | D39: =IF(C39="","",C39/$D$18) -> 0.040516772 | E39: max | F39: =$D$15 -> 0.12 | G39: =IF(D39="","",IF(D39>F39,"breach","ok")) -> ok | H39: =IF(C39="","",C39-F39*$D$18) -> -32604.06 | I39: =IF(H39="","",H39/$D$18) -> -0.079483228
A40: IPS-4.1 | B40: TLT | C40: =Positions!H11 -> 40975 | D40: =IF(C40="","",C40/$D$18) -> 0.099890176 | E40: max | F40: =$D$15 -> 0.12 | G40: =IF(D40="","",IF(D40>F40,"breach","ok")) -> ok | H40: =IF(C40="","",C40-F40*$D$18) -> -8249.06 | I40: =IF(H40="","",H40/$D$18) -> -0.020109824
A41: IPS-4.1 | B41: GLD | C41: =Positions!H12 -> 40278 | D41: =IF(C41="","",C41/$D$18) -> 0.098191007 | E41: max | F41: =$D$15 -> 0.12 | G41: =IF(D41="","",IF(D41>F41,"breach","ok")) -> ok | H41: =IF(C41="","",C41-F41*$D$18) -> -8946.06 | I41: =IF(H41="","",H41/$D$18) -> -0.021808993
A42: IPS-4.1 | B42: VNQ | C42: =Positions!H13 -> 28734 | D42: =IF(C42="","",C42/$D$18) -> 0.070048671 | E42: max | F42: =$D$15 -> 0.12 | G42: =IF(D42="","",IF(D42>F42,"breach","ok")) -> ok | H42: =IF(C42="","",C42-F42*$D$18) -> -20490.06 | I42: =IF(H42="","",H42/$D$18) -> -0.049951329
A44: Instrument type (needed by IPS-4.2; the code will carry this on Asset.instrument_type)
...

Sheet Ledger
A1: Part 8 — The transaction ledger
A2: Decisions D10–D14: average cost; fees in cost basis; a sale keeps the average and releases quantity × average; holdings derive from rows; a row belongs to a portfolio. Blue = typed input, black = formula.
A4: A. Portfolio 3 as a ledger — must reproduce Positions!D, E, F and K to the cent
A5: Date | B5: Type | C5: Ticker | D5: Qty | E5: Price | F5: Fees | G5: Amount
A6: 2024-01-15 | B6: buy | C6: SPY | D6: 100 | E6: 500 | F6: 0 | G6: =IF(B6="buy",D6*E6+F6,D6*E6-F6) -> 50000
A7: 2024-02-20 | B7: buy | C7: AAPL | D7: 200 | E7: 200 | F7: 0 | G7: =IF(B7="buy",D7*E7+F7,D7*E7-F7) -> 40000
A8: 2024-03-18 | B8: buy | C8: MSFT | D8: 100 | E8: 400 | F8: 0 | G8: =IF(B8="buy",D8*E8+F8,D8*E8-F8) -> 40000
A9: 2024-05-06 | B9: buy | C9: JNJ | D9: 150 | E9: 150 | F9: 0 | G9: =IF(B9="buy",D9*E9+F9,D9*E9-F9) -> 22500
A10: 2024-07-15 | B10: buy | C10: JPM | D10: 100 | E10: 200 | F10: 0 | G10: =IF(B10="buy",D10*E10+F10,D10*E10-F10) -> 20000
A11: 2024-09-09 | B11: buy | C11: NEE | D11: 200 | E11: 75 | F11: 0 | G11: =IF(B11="buy",D11*E11+F11,D11*E11-F11) -> 15000
A12: 2025-01-13 | B12: buy | C12: TLT | D12: 500 | E12: 90 | F12: 0 | G12: =IF(B12="buy",D12*E12+F12,D12*E12-F12) -> 45000
A13: 2025-03-10 | B13: buy | C13: GLD | D13: 100 | E13: 250 | F13: 0 | G13: =IF(B13="buy",D13*E13+F13,D13*E13-F13) -> 25000
A14: 2025-06-02 | B14: buy | C14: VNQ | D14: 300 | E14: 90 | F14: 0 | G14: =IF(B14="buy",D14*E14+F14,D14*E14-F14) -> 27000
F15: Total | G15: =SUM(G6:G14) -> 284500
A17: Holdings derived from the rows above (D13), checked against Positions. First buy = first matching row; the ledger is in date order.
A18: Ticker | B18: Qty | C18: Cost basis | D18: Average | E18: First buy | F18: Positions cost | G18: Difference
A19: SPY | B19: =SUMIFS($D$6:$D$14,$C$6:$C$14,A19,$B$6:$B$14,"buy")-SUMIFS($D$6:$D$14,$C$6:$C$14,A19,$B$6:$B$14,"sell") -> 100 | C19: =SUMIFS($G$6:$G$14,$C$6:$C$14,A19,$B$6:$B$14,"buy") -> 50000 | D19: =C19/B19 -> 500 | E19: =INDEX($A$6:$A$14,MATCH(A19,$C$6:$C$14,0)) -> 2024-01-15 | F19: =Positions!F5 -> 50000 | G19: =C19-F19 -> 0
A20: AAPL | B20: =SUMIFS($D$6:$D$14,$C$6:$C$14,A20,$B$6:$B$14,"buy")-SUMIFS($D$6:$D$14,$C$6:$C$14,A20,$B$6:$B$14,"sell") -> 200 | C20: =SUMIFS($G$6:$G$14,$C$6:$C$14,A20,$B$6:$B$14,"buy") -> 40000 | D20: =C20/B20 -> 200 | E20: =INDEX($A$6:$A$14,MATCH(A20,$C$6:$C$14,0)) -> 2024-02-20 | F20: =Positions!F6 -> 40000 | G20: =C20-F20 -> 0
A21: MSFT | B21: =SUMIFS($D$6:$D$14,$C$6:$C$14,A21,$B$6:$B$14,"buy")-SUMIFS($D$6:$D$14,$C$6:$C$14,A21,$B$6:$B$14,"sell") -> 100 | C21: =SUMIFS($G$6:$G$14,$C$6:$C$14,A21,$B$6:$B$14,"buy") -> 40000 | D21: =C21/B21 -> 400 | E21: =INDEX($A$6:$A$14,MATCH(A21,$C$6:$C$14,0)) -> 2024-03-18 | F21: =Positions!F7 -> 40000 | G21: =C21-F21 -> 0
A22: JNJ | B22: =SUMIFS($D$6:$D$14,$C$6:$C$14,A22,$B$6:$B$14,"buy")-SUMIFS($D$6:$D$14,$C$6:$C$14,A22,$B$6:$B$14,"sell") -> 150 | C22: =SUMIFS($G$6:$G$14,$C$6:$C$14,A22,$B$6:$B$14,"buy") -> 22500 | D22: =C22/B22 -> 150 | E22: =INDEX($A$6:$A$14,MATCH(A22,$C$6:$C$14,0)) -> 2024-05-06 | F22: =Positions!F8 -> 22500 | G22: =C22-F22 -> 0
A23: JPM | B23: =SUMIFS($D$6:$D$14,$C$6:$C$14,A23,$B$6:$B$14,"buy")-SUMIFS($D$6:$D$14,$C$6:$C$14,A23,$B$6:$B$14,"sell") -> 100 | C23: =SUMIFS($G$6:$G$14,$C$6:$C$14,A23,$B$6:$B$14,"buy") -> 20000 | D23: =C23/B23 -> 200 | E23: =INDEX($A$6:$A$14,MATCH(A23,$C$6:$C$14,0)) -> 2024-07-15 | F23: =Positions!F9 -> 20000 | G23: =C23-F23 -> 0
A24: NEE | B24: =SUMIFS($D$6:$D$14,$C$6:$C$14,A24,$B$6:$B$14,"buy")-SUMIFS($D$6:$D$14,$C$6:$C$14,A24,$B$6:$B$14,"sell") -> 200 | C24: =SUMIFS($G$6:$G$14,$C$6:$C$14,A24,$B$6:$B$14,"buy") -> 15000 | D24: =C24/B24 -> 75 | E24: =INDEX($A$6:$A$14,MATCH(A24,$C$6:$C$14,0)) -> 2024-09-09 | F24: =Positions!F10 -> 15000 | G24: =C24-F24 -> 0
A25: TLT | B25: =SUMIFS($D$6:$D$14,$C$6:$C$14,A25,$B$6:$B$14,"buy")-SUMIFS($D$6:$D$14,$C$6:$C$14,A25,$B$6:$B$14,"sell") -> 500 | C25: =SUMIFS($G$6:$G$14,$C$6:$C$14,A25,$B$6:$B$14,"buy") -> 45000 | D25: =C25/B25 -> 90 | E25: =INDEX($A$6:$A$14,MATCH(A25,$C$6:$C$14,0)) -> 2025-01-13 | F25: =Positions!F11 -> 45000 | G25: =C25-F25 -> 0
A26: GLD | B26: =SUMIFS($D$6:$D$14,$C$6:$C$14,A26,$B$6:$B$14,"buy")-SUMIFS($D$6:$D$14,$C$6:$C$14,A26,$B$6:$B$14,"sell") -> 100 | C26: =SUMIFS($G$6:$G$14,$C$6:$C$14,A26,$B$6:$B$14,"buy") -> 25000 | D26: =C26/B26 -> 250 | E26: =INDEX($A$6:$A$14,MATCH(A26,$C$6:$C$14,0)) -> 2025-03-10 | F26: =Positions!F12 -> 25000 | G26: =C26-F26 -> 0
A27: VNQ | B27: =SUMIFS($D$6:$D$14,$C$6:$C$14,A27,$B$6:$B$14,"buy")-SUMIFS($D$6:$D$14,$C$6:$C$14,A27,$B$6:$B$14,"sell") -> 300 | C27: =SUMIFS($G$6:$G$14,$C$6:$C$14,A27,$B$6:$B$14,"buy") -> 27000 | D27: =C27/B27 -> 90 | E27: =INDEX($A$6:$A$14,MATCH(A27,$C$6:$C$14,0)) -> 2025-06-02 | F27: =Positions!F13 -> 27000 | G27: =C27-F27 -> 0
B28: Total | C28: =SUM(C19:C27) -> 284500 | F28: =SUM(F19:F27) -> 284500 | G28: =C28-F28 -> 0
A30: B. One position (KO) built in two tranches and partly sold — running position after each row
A31: Date | B31: Type | C31: Qty | D31: Price | E31: Fees | F31: Amount | G31: Qty after | H31: Cost basis after | I31: Average after | J31: Released | K31: Realized
A32: 2024-09-09 | B32: buy | C32: 200 | D32: 75 | E32: 0 | F32: =IF(B32="buy",C32*D32+E32,C32*D32-E32) -> 15000 | G32: =IF(B32="buy",0+C32,0-C32) -> 200 | H32: =IF(B32="buy",0+F32,0-J32) -> 15000 | I32: =H32/G32 -> 75 | J32: ="" | K32: =IF(B32="sell",F32-J32,"")
A33: 2025-02-03 | B33: buy | C33: 100 | D33: 90 | E33: 3 | F33: =IF(B33="buy",C33*D33+E33,C33*D33-E33) -> 9003 | G33: =IF(B33="buy",G32+C33,G32-C33) -> 300 | H33: =IF(B33="buy",H32+F33,H32-J33) -> 24003 | I33: =H33/G33 -> 80.01 | J33: =IF(B33="sell",C33*I32,"") | K33: =IF(B33="sell",F33-J33,"")
A34: 2025-11-17 | B34: sell | C34: 50 | D34: 85 | E34: 2 | F34: =IF(B34="buy",C34*D34+E34,C34*D34-E34) -> 4248 | G34: =IF(B34="buy",G33+C34,G33-C34) -> 250 | H34: =IF(B34="buy",H33+F34,H33-J34) -> 20002.5 | I34: =H34/G34 -> 80.01 | J34: =IF(B34="sell",C34*I33,"") -> 4000.5 | K34: =IF(B34="sell",F34-J34,"") -> 247.5
A36: Price now | B36: 88
A37: Market value | B37: =G34*B36 -> 22000
A38: P&L abs | B38: =B37-H34 -> 1997.5
A39: P&L % | B39: =B38/H34 -> 0.099862517
A41: Hand-computed (expected_values.md Part 8): after the sale 250 @ 80.01, cost basis 20,002.50, realized 247.50; at 88.00 market value 22,000.00, P&L +1,997.50 (+9.99%).
A43: C. One foreign-currency position in a euro portfolio — D15–D18. Base currency EUR; AAPL quoted in USD; rates are EUR per USD, stated and synthetic.
A44: Date | B44: Type | C44: Qty | D44: Price (USD) | E44: Rate EUR/USD | F44: Fees (EUR) | G44: Amount (EUR)
A45: 2024-02-20 | B45: buy | C45: 100 | D45: 200 | E45: 0.92 | F45: 5 | G45: =IF(B45="buy",C45*D45*E45+F45,C45*D45*E45-F45) -> 18405
A47: Position after (D13, D18: in EUR)
...

Sheet Prices
A1: Part 9 — The price source
A2: Decisions D19–D20: a close is the exchange's as-traded print, split-adjusted only; when two sources disagree the exchange's print wins and nothing averages. Blue = typed from the exchange's own historical quotes (api.nasdaq.com, Close/Last), fetched 2026-09-10; black = formula. Tolerance: equal after rounding to the cent.
A4: A. The valuation date, 2026-09-02 — the exchange against Positions!G (Part 1)
A5: Ticker | B5: Exchange 2026-09-02 | C5: Part 1 (Positions) | D5: Difference | E5: Verdict
A6: SPY | B6: 765.16 | C6: =Positions!G5 -> 765.16 | D6: =ROUND(C6,2)-ROUND(B6,2) -> 0 | E6: =IF(ABS(D6)<0.005,"agrees","DISAGREES") -> agrees
A7: AAPL | B7: 324.96 | C7: =Positions!G6 -> 324.96 | D7: =ROUND(C7,2)-ROUND(B7,2) -> 0 | E7: =IF(ABS(D7)<0.005,"agrees","DISAGREES") -> agrees
A8: MSFT | B8: 496.82 | C8: =Positions!G7 -> 496.82 | D8: =ROUND(C8,2)-ROUND(B8,2) -> 0 | E8: =IF(ABS(D8)<0.005,"agrees","DISAGREES") -> agrees
A9: JNJ | B9: 275.21 | C9: =Positions!G8 -> 275.21 | D9: =ROUND(C9,2)-ROUND(B9,2) -> 0 | E9: =IF(ABS(D9)<0.005,"agrees","DISAGREES") -> agrees
A10: JPM | B10: 356.22 | C10: =Positions!G9 -> 356.22 | D10: =ROUND(C10,2)-ROUND(B10,2) -> 0 | E10: =IF(ABS(D10)<0.005,"agrees","DISAGREES") -> agrees
A11: NEE | B11: 83.1 | C11: =Positions!G10 -> 83.1 | D11: =ROUND(C11,2)-ROUND(B11,2) -> 0 | E11: =IF(ABS(D11)<0.005,"agrees","DISAGREES") -> agrees
A12: TLT | B12: 81.95 | C12: =Positions!G11 -> 81.95 | D12: =ROUND(C12,2)-ROUND(B12,2) -> 0 | E12: =IF(ABS(D12)<0.005,"agrees","DISAGREES") -> agrees
A13: GLD | B13: 402.78 | C13: =Positions!G12 -> 402.78 | D13: =ROUND(C13,2)-ROUND(B13,2) -> 0 | E13: =IF(ABS(D13)<0.005,"agrees","DISAGREES") -> agrees
A14: VNQ | B14: 95.78 | C14: =Positions!G13 -> 95.78 | D14: =ROUND(C14,2)-ROUND(B14,2) -> 0 | E14: =IF(ABS(D14)<0.005,"agrees","DISAGREES") -> agrees
A15: Agreeing | B15: =COUNTIF(E6:E14,"agrees") -> 9 | C15: of 9
A17: B. Dates before a dividend — the falsifier. The committed series is benchmark_closes.csv (Part 4's 252 closes); the database column is data/portfolio.db as read on 2026-09-10, after the provider had refetched with its default.
A18: Ticker | B18: Date | C18: Exchange | D18: Committed series | E18: Database 2026-09-10 | F18: Series minus exchange | G18: Database minus exchange | H18: Verdict
A19: JNJ | B19: 2026-08-21 | C19: 270.24 | D19: 270.24 | E19: 268.9137 | F19: =ROUND(D19,2)-ROUND(C19,2) -> 0 | G19: =ROUND(E19,2)-ROUND(C19,2) -> -1.33 | H19: =IF(ABS(G19)<0.005,"database agrees",IF(ABS(F19)<0.005,"database wrong, series is the print","both differ")) -> database wrong, series is the print
A20: TLT | B20: 2026-08-28 | C20: 82.88 | D20: 82.88 | E20: 82.5636 | F20: =ROUND(D20,2)-ROUND(C20,2) -> 0 | G20: =ROUND(E20,2)-ROUND(C20,2) -> -0.32 | H20: =IF(ABS(G20)<0.005,"database agrees",IF(ABS(F20)<0.005,"database wrong, series is the print","both differ")) -> database wrong, series is the print
A22: Over the whole fetch (20 August to 3 September, 99 rows): 90 rows lie inside the committed series and all 90 agree to the cent; the database agrees on 82 and is lower on 17, every one a JNJ, NEE or TLT row before that holding's latest ex-dividend date. Cause: the provider's history call uses the library default, which returns the dividend-adjusted close. Fix at the provider; the reference does not move (D20).
A24: Hand-computed (expected_values.md Part 9): nine of nine on 2026-09-02; JNJ 2026-08-21 database 268.91 against the print 270.24; TLT 2026-08-28 82.56 against 82.88.

Sheet Philosophy
A1: Part 10 — The philosophy check against docs/PHILOSOPHY.md
A2: Synthetic figures for candidate W-1 (docs/WATCHLIST.md), typed inputs in bold as on the Compliance sheet; everything else computes. Reference for the checker's arithmetic, not for the company. As-of 2026-09-10; FY2021 to FY2025 reported by then (D21). Filed dates are synthetic, about five weeks after each year end; D21 counts a year by them.
A3: D22: a clause over n years is one finding decided by the worst year (MIN for a floor, MAX for a ceiling). D23: exactly at the limit passes; status formulas use strict < and >. D24: one formula per metric key, as in Part 10 B. D25: a missing figure stops the whole check, not modelled as a formula.
A4: Distance is signed so that positive = failure: limit − observed against a floor, observed − limit against a ceiling, in the metric's own unit.
A6: A. Reported figures, USD millions
A7: FY | B7: Ends | C7: Filed | D7: Revenue | E7: Gross profit | F7: Operating income | G7: Tax rate | H7: D&A | I7: Operating cash flow | J7: Capex | K7: Equity | L7: Debt | M7: Cash
A8: FY2021 | B8: 2021-12-31 | C8: 2022-02-04 | F8: 20000 | G8: 0.2 | K8: 120000 | L8: 20000 | M8: 40000
A9: FY2022 | B9: 2022-12-31 | C9: 2023-02-03 | F9: 13500 | G9: 0.2 | K9: 128000 | L9: 22000 | M9: 42000
A10: FY2023 | B10: 2023-12-31 | C10: 2024-02-02 | D10: 100000 | E10: 55000 | F10: 24000 | G10: 0.2 | K10: 140000 | L10: 20000 | M10: 40000
A11: FY2024 | B11: 2024-12-31 | C11: 2025-02-05 | D11: 112000 | E11: 63840 | F11: 30000 | G11: 0.2 | K11: 150000 | L11: 18000 | M11: 43000
A12: FY2025 | B12: 2025-12-31 | C12: 2026-02-04 | D12: 125000 | E12: 72500 | F12: 36000 | G12: 0.2 | H12: 16000 | I12: 52780 | J12: 22000 | K12: 170000 | L12: 16000 | M12: 42000
A14: Shares outstanding (millions) | B14: 4000
A15: Price, as of 2026-09-10 | B15: 171
A16: Valuation range low, as of 2026-09-10 | B16: 180
A17: Valuation range high, as of 2026-09-10 | B17: 240
A19: C. Metrics by year (Part 10 B formulas)
A20: FY | B20: Invested capital | C20: NOPAT | D20: ROIC | E20: Gross margin
A21: =A8 -> FY2021 | B21: =K8+L8-M8 -> 100000 | C21: =F8*(1-G8) -> 16000 | D21: =C21/B21 -> 0.16
A22: =A9 -> FY2022 | B22: =K9+L9-M9 -> 108000 | C22: =F9*(1-G9) -> 10800 | D22: =C22/B22 -> 0.1
A23: =A10 -> FY2023 | B23: =K10+L10-M10 -> 120000 | C23: =F10*(1-G10) -> 19200 | D23: =C23/B23 -> 0.16 | E23: =E10/D10 -> 0.55
A24: =A11 -> FY2024 | B24: =K11+L11-M11 -> 125000 | C24: =F11*(1-G11) -> 24000 | D24: =C24/B24 -> 0.192 | E24: =E11/D11 -> 0.57
A25: =A12 -> FY2025 | B25: =K12+L12-M12 -> 144000 | C25: =F12*(1-G12) -> 28800 | D25: =C25/B25 -> 0.2 | E25: =E12/D12 -> 0.58
A27: FY2025 net debt | B27: =L12-M12 -> -26000
A28: FY2025 EBITDA | B28: =F12+H12 -> 52000
A29: net_debt_to_ebitda | B29: =B27/B28 -> -0.5
A30: FY2025 free cash flow | B30: =I12-J12 -> 30780
A31: Market value at the as-of price | B31: =B15*B14 -> 684000
A32: free_cash_flow_yield | B32: =B30/B31 -> 0.045
A33: Discount to the low end of the range | B33: =1-B15/B16 -> 0.05
A35: Limits from docs/PHILOSOPHY.md
A36: Clause | B36: Metric | C36: Bound | D36: Limit | E36: Years | F36: Source
A37: PHI-2.1 | B37: return_on_invested_capital | C37: min | D37: 0.12 | E37: 5 | F37: docs/PHILOSOPHY.md
A38: PHI-2.2 | B38: gross_margin | C38: min | D38: 0.35 | E38: 3 | F38: docs/PHILOSOPHY.md
A39: PHI-3.1 | B39: net_debt_to_ebitda | C39: max | D39: 2 | E39: 1 | F39: docs/PHILOSOPHY.md
A40: PHI-4.1 | B40: discount to the low end of the range | C40: min | D40: 0.25 | F40: docs/PHILOSOPHY.md
A41: PHI-4.2 | B41: free_cash_flow_yield | C41: min | D41: 0.04 | E41: 1 | F41: docs/PHILOSOPHY.md
A43: D. Findings
A44: Clause | B44: Metric | C44: Years read | D44: Deciding year | E44: Observed | F44: Limit | G44: Bound | H44: Status | I44: Distance
A45: =A37 -> PHI-2.1 | B45: =B37 -> return_on_invested_capital | C45: FY2021 to FY2025 | D45: =INDEX(A21:A25,MATCH(MIN(D21:D25),D21:D25,0)) -> FY2022 | E45: =MIN(D21:D25) -> 0.1 | F45: =D37 -> 0.12 | G45: =C37 -> min | H45: =IF(E45<F45,"fail","pass") -> fail | I45: =F45-E45 -> 0.02
A46: =A38 -> PHI-2.2 | B46: =B38 -> gross_margin | C46: FY2023 to FY2025 | D46: =INDEX(A23:A25,MATCH(MIN(E23:E25),E23:E25,0)) -> FY2023 | E46: =MIN(E23:E25) -> 0.55 | F46: =D38 -> 0.35 | G46: =C38 -> min | H46: =IF(E46<F46,"fail","pass") -> pass | I46: =F46-E46 -> -0.2
...

Sheet Filings
A1: Part 12 — The filings reader
A2: Decisions D26–D33. EDGAR company facts for Apple Inc. (CIK 320193), pulled 2026-09-11; the facts are committed as tests/golden/edgar_facts_aapl.csv and the 3.79 MB document is not. Blue = typed by the owner from Apple's own filing (the second source, Part 9's pattern); black = EDGAR's figure or a formula. USD millions. Tolerance: equal to the dollar.
